Workbook

Sheet Summary
A1: Promo Hub – Global Entity Database
A2: All entries are PROSPECTS (outreach targets), not partners. Submission terms are based on public information and may have changed – verify on the official website before contacting or publishing.
A4: Total entities | B4: =COUNTA(Database!A2:A549) -> 548
A5: Countries (incl. Worldwide) | B5: =SUMPRODUCT(1/COUNTIF(Database!E2:E549,Database!E2:E549)) -> 46
A7: By creator type | B7: Count
A8: Musician | B8: =COUNTIF(Database!C2:C549,"*Musician*") -> 363
A9: DJ / producer | B9: =COUNTIF(Database!C2:C549,"*DJ / producer*") -> 236
A10: Writer | B10: =COUNTIF(Database!C2:C549,"*Writer*") -> 153
A12: By region | B12: Count
A13: Europe | B13: =COUNTIF(Database!F2:F549,A13) -> 314
A14: North America | B14: =COUNTIF(Database!F2:F549,A14) -> 176
A15: Latin America | B15: =COUNTIF(Database!F2:F549,A15) -> 11
A16: Africa | B16: =COUNTIF(Database!F2:F549,A16) -> 7
A17: Asia | B17: =COUNTIF(Database!F2:F549,A17) -> 13
A18: Middle East | B18: =COUNTIF(Database!F2:F549,A18) -> 6
A19: Oceania | B19: =COUNTIF(Database!F2:F549,A19) -> 16
A20: Worldwide | B20: =COUNTIF(Database!F2:F549,A20) -> 5
A22: By type | B22: Count
A23: Blog | B23: =COUNTIF(Database!B2:B549,A23) -> 4
A24: Bookshop | B24: =COUNTIF(Database!B2:B549,A24) -> 3
A25: College radio | B25: =COUNTIF(Database!B2:B549,A25) -> 12
A26: Community | B26: =COUNTIF(Database!B2:B549,A26) -> 7
A27: Distributor | B27: =COUNTIF(Database!B2:B549,A27) -> 12
A28: E-book / audio / self-pub | B28: =COUNTIF(Database!B2:B549,A28) -> 20
A29: FM / DAB radio | B29: =COUNTIF(Database!B2:B549,A29) -> 94
A30: Festival / fair / showcase | B30: =COUNTIF(Database!B2:B549,A30) -> 93
A31: Funding / export office | B31: =COUNTIF(Database!B2:B549,A31) -> 16
A32: Live / venue series | B32: =COUNTIF(Database!B2:B549,A32) -> 1
A33: Magazine | B33: =COUNTIF(Database!B2:B549,A33) -> 29
A34: Mix series | B34: =COUNTIF(Database!B2:B549,A34) -> 4
A35: Newsletter | B35: =COUNTIF(Database!B2:B549,A35) -> 5
A36: Online radio | B36: =COUNTIF(Database!B2:B549,A36) -> 24
A37: Other (prizes, contests) | B37: =COUNTIF(Database!B2:B549,A37) -> 6
A38: Platform / tool | B38: =COUNTIF(Database!B2:B549,A38) -> 37
A39: Playlist | B39: =COUNTIF(Database!B2:B549,A39) -> 2
A40: Press / media | B40: =COUNTIF(Database!B2:B549,A40) -> 77
A41: Publisher | B41: =COUNTIF(Database!B2:B549,A41) -> 18
A42: Record label | B42: =COUNTIF(Database!B2:B549,A42) -> 25
A43: Record pool | B43: =COUNTIF(Database!B2:B549,A43) -> 8
A44: Rights organisation | B44: =COUNTIF(Database!B2:B549,A44) -> 30
...

Sheet Database
A1: Name | B1: Type | C1: Creators | D1: Country | E1: Country code | F1: Region | G1: Website | H1: How to reach | I1: Proposed model | J1: Recommended level (1–5) | K1: Note (EN) | L1: Note (PL) | M1: Stage | N1: Verified
A2: Aké Arts and Book Festival | B2: Festival / fair / showcase | C2: Writer | D2: Nigeria | E2: NG | F2: Africa | G2: https://akefestival.org/ | H2: Curated / invitation | I2: Barter | J2: 3 | K2: Literary festival with a curated programme. | L2: Festiwal literacki z kuratorowanym programem. | M2: prospect | N2: no
A3: The NATIVE | B3: Press / media | C3: Musician | D3: Nigeria | E3: NG | F3: Africa | G3: https://thenativemag.com/ | H3: Editorial / A&R contact | I3: Free | J3: 2 | K3: African music and culture media. | L3: Media o muzyce i kulturze afrykańskiej. | M3: prospect | N3: no
A4: Nyege Nyege | B4: Festival / fair / showcase | C4: Musician, DJ / producer | D4: Uganda | E4: UG | F4: Africa | G4: https://nyegenyege.com/ | H4: Curated / invitation | I4: Barter | J4: 3 | K4: Electronic music festival / conference. | L4: Festiwal / konferencja muzyki elektronicznej. | M4: prospect | N4: no
A5: Cape Town International Jazz Festival | B5: Festival / fair / showcase | C5: Musician | D5: South Africa | E5: ZA | F5: Africa | G5: https://www.capetownjazzfest.com/ | H5: Curated / invitation | I5: Barter | J5: 3 | K5: Major festival with a curated line-up. | L5: Duży festiwal z kuratorowanym line-upem. | M5: prospect | N5: no
A6: 5FM (SABC) | B6: FM / DAB radio | C6: Musician, DJ / producer | D6: South Africa | E6: ZA | F6: Africa | G6: https://www.5fm.co.za/ | H6: Editorial / A&R contact | I6: Free | J6: 3 | K6: Public station for young audiences with new-music shows. | L6: Publiczna stacja dla młodych z audycjami o nowej muzyce. | M6: prospect | N6: no
A7: Metro FM (SABC) | B7: FM / DAB radio | C7: Musician | D7: South Africa | E7: ZA | F7: Africa | G7: https://www.metrofm.co.za/ | H7: Editorial / A&R contact | I7: Free | J7: 3 | K7: Major commercial station – realistic for established artists. | L7: Duża stacja komercyjna – realny cel dla uznanych artystów. | M7: prospect | N7: no
A8: SAMRO | B8: Rights organisation | C8: Musician | D8: South Africa | E8: ZA | F8: Africa | G8: https://www.samro.org.za/ | H8: Open submissions | I8: Free | J8: 1 | K8: Collecting society for authors – register works to collect royalties. | L8: Organizacja zbiorowego zarządzania prawami autorów – rejestruj utwory, by pobierać tantiemy. | M8: prospect | N8: no
A9: Clockenflap | B9: Festival / fair / showcase | C9: Musician, DJ / producer | D9: Hong Kong | E9: HK | F9: Asia | G9: https://www.clockenflap.com/ | H9: Curated / invitation | I9: Barter | J9: 3 | K9: Major festival with a curated line-up. | L9: Duży festiwal z kuratorowanym line-upem. | M9: prospect | N9: no
A10: Jaipur Literature Festival | B10: Festival / fair / showcase | C10: Writer | D10: India | E10: IN | F10: Asia | G10: https://jaipurliteraturefestival.org/ | H10: Curated / invitation | I10: Barter | J10: 4 | K10: Literary festival with a curated programme. | L10: Festiwal literacki z kuratorowanym programem. | M10: prospect | N10: no
A11: NH7 Weekender | B11: Festival / fair / showcase | C11: Musician, DJ / producer | D11: India | E11: IN | F11: Asia | G11: https://www.nh7.in/ | H11: Curated / invitation | I11: Barter | J11: 3 | K11: Major festival with a curated line-up. | L11: Duży festiwal z kuratorowanym line-upem. | M11: prospect | N11: no
A12: Rolling Stone India | B12: Press / media | C12: Musician | D12: India | E12: IN | F12: Asia | G12: https://rollingstoneindia.com/ | H12: Editorial / A&R contact | I12: Free | J12: 2 | K12: Music publication – pitch premieres, reviews or features. | L12: Medium muzyczne – pitch premier, recenzji lub artykułów. | M12: prospect | N12: no
A13: Fuji Rock Festival | B13: Festival / fair / showcase | C13: Musician, DJ / producer | D13: Japan | E13: JP | F13: Asia | G13: https://www.fujirockfestival.com/ | H13: Curated / invitation | I13: Barter | J13: 4 | K13: Major festival with a curated line-up. | L13: Duży festiwal z kuratorowanym line-upem. | M13: prospect | N13: no
... A549: SoundCampaign | B549: Platform / tool | C549: Musician | D549: Worldwide | E549: WW | F549: Worldwide | G549: https://soundcampaign.com/ | H549: Paid service | I549: Review fee | J549: 1 | K549: Paid submission platform – benchmark or possible integration. | L549: Płatna platforma zgłoszeń – benchmark lub możliwa integracja. | M549: prospect | N549: no
